Workbook

Sheet Sheet1
A1: Date: | B1: 2025-04-01 to 2025-04-18
A2: Name: | B2: Item Wise: Sales Report
A3: Restaurant Name: | B3: Lá gioia
A6: Category | B6: Item | C6: Code | D6: Sap Code | E6: Qty. | F6: Total (₹)
A7: Total | E7: 3585 | F7: 1346595
A8: Min. | E8: 1 | F8: 0
A9: Max. | E9: 128 | F9: 49600
A10: Avg. | E10: 11.49 | F10: 4316.01
A11: To Share | B11: Frittini Veg | C11: 7 [U] | E11: 39 | F11: 12675
B12: Frittini Non Veg | C12: 8 [U] | E12: 21 | F12: 12075
B13: Tagliere Di Formaggi | C13: 9 [U] | E13: 20 | F13: 18900
B14: Tagliere Di Salumi | C14: 10 [U] | E14: 34 | F14: 32130
A15: Sub Total | E15: 114 | F15: 75780
A16: Bruschette | B16: Bruschetta Alle Melanzane | C16: 11 [U] | E16: 18 | F16: 5310
B17: Bruschetta Alla Stracciatella | C17: 12 [U] | E17: 67 | F17: 23450
B18: Bruschetta Alla Nduja | C18: 13 [U] | E18: 12 | F18: 4200
B19: Bruschetta Con Pate' Di Olive | C19: 14 [U] | E19: 20 | F19: 5900
A20: Sub Total | E20: 117 | F20: 38860
A21: Zuppe (Soups) | B21: Vellutata Di Zucca Con Funghi | C21: 15 [U] | E21: 30 | F21: 9100
B22: Minestrone Con Polpette | C22: 16 [U] | E22: 15 | F22: 5475
A23: Sub Total | E23: 45 | F23: 14575
A24: Salads | B24: Insalata Mista Con Mozzarella Salad | C24: 17 [U] | E24: 24 | F24: 7150
B25: Insalata Mista Con Pollo Salad | C25: 18 [U] | E25: 19 | F25: 3450
A26: Sub Total | E26: 43 | F26: 10600
A27: Primi (Mains) | B27: Foglie Di Ulivo Pugliesi | C27: 19 [U] | E27: 64 | F27: 31680
B28: Cannelloni Ricotta E Spinaci | C28: 20 [U] | E28: 49 | F28: 28560
B29: Orecchiette Alla Barese | C29: 21 [U] | E29: 20 | F29: 7900
B30: Risotto Meneghino | C30: 22 [U] | E30: 24 | F30: 11880
B31: Gnocchi Su Crema Di Zucca | C31: 23 [U] | E31: 18 | F31: 10710
B32: Gnocchi Al Pesto Di Basilico | C32: 24 [U] | E32: 46 | F32: 22275
B33: Ravioli Al Pesto Al Pistacchio | C33: 25 [U] | E33: 65 | F33: 49600
B34: Fettuccine Al Ragu' | C34: 26 [U] | E34: 64 | F34: 28210
B35: Lasagna Alla Bolognese | C35: 27 [U] | E35: 20 | F35: 8190
B36: Bucatini Amatriciana | C36: 29 [U] | E36: 15 | F36: 14250
B37: Ravioli Con Tonno E Pomodorini | C37: 30 [U] | E37: 11 | F37: 9405
B38: Bigoli Neri Ai Gamberi | C38: 31 [U] | E38: 15 | F38: 7630
B39: Lasagna Alla Bolognese Chicken | C39: Lasagna Alla Bologne | E39: 6 | F39: 2730
A40: Sub Total | E40: 417 | F40: 233020
A41: Dolci (Desserts) | B41: Tiramisu | C41: 40 [U] | E41: 116 | F41: 41580
B42: Pasticciotto | C42: 41 [U] | E42: 28 | F42: 6075
...

Sheet raw_material_final
A1: Items from recipe | B1: Department | C1: RawMaterial | D1: Qty | E1: Unit | F1: Area
A2: Frittini Veg | B2: =_xlfn.XLOOKUP(A2,[1]Table0!$A:$A,[1]Table0!$B:$B) -> Italian 1 | C2: =_xlfn.XLOOKUP($E2,raw_materials!$B:$B,raw_materials!#REF!) -> Pittula | D2: =_xlfn.XLOOKUP($E2,raw_materials!$B:$B,raw_materials!A:A) -> 120 | E2: =_xlfn.XLOOKUP($E2,raw_materials!$B:$B,raw_materials!B:B) -> GM | F2: =_xlfn.XLOOKUP($E2,raw_materials!$B:$B,raw_materials!C:C) -> All
A3: Frittini Non Veg | B3: =_xlfn.XLOOKUP(A3,[1]Table0!$A:$A,[1]Table0!$B:$B) -> Italian 1 | C3: =_xlfn.XLOOKUP($E3,raw_materials!$B:$B,raw_materials!#REF!) -> Crocchette Di Patate | D3: =_xlfn.XLOOKUP($E3,raw_materials!$B:$B,raw_materials!A:A) -> 150 | E3: =_xlfn.XLOOKUP($E3,raw_materials!$B:$B,raw_materials!B:B) -> GM | F3: =_xlfn.XLOOKUP($E3,raw_materials!$B:$B,raw_materials!C:C) -> All
A4: Tagliere Di Formaggi | B4: =_xlfn.XLOOKUP(A4,[1]Table0!$A:$A,[1]Table0!$B:$B) -> Italian 1 | C4: =_xlfn.XLOOKUP($E4,raw_materials!$B:$B,raw_materials!#REF!) -> Grana Padano | D4: =_xlfn.XLOOKUP($E4,raw_materials!$B:$B,raw_materials!A:A) -> 30 | E4: =_xlfn.XLOOKUP($E4,raw_materials!$B:$B,raw_materials!B:B) -> GM | F4: =_xlfn.XLOOKUP($E4,raw_materials!$B:$B,raw_materials!C:C) -> All
A5: Tagliere Di Salumi | B5: =_xlfn.XLOOKUP(A5,[1]Table0!$A:$A,[1]Table0!$B:$B) -> Italian 1 | C5: =_xlfn.XLOOKUP($E5,raw_materials!$B:$B,raw_materials!#REF!) -> Cooked Ham | D5: =_xlfn.XLOOKUP($E5,raw_materials!$B:$B,raw_materials!A:A) -> 30 | E5: =_xlfn.XLOOKUP($E5,raw_materials!$B:$B,raw_materials!B:B) -> GM | F5: =_xlfn.XLOOKUP($E5,raw_materials!$B:$B,raw_materials!C:C) -> All
A6: Bruschetta Alle Melanzane | B6: =_xlfn.XLOOKUP(A6,[1]Table0!$A:$A,[1]Table0!$B:$B) -> Pizza 1 | C6: =_xlfn.XLOOKUP($E6,raw_materials!$B:$B,raw_materials!#REF!) -> Impasto Bruschetta | D6: =_xlfn.XLOOKUP($E6,raw_materials!$B:$B,raw_materials!A:A) -> 100 | E6: =_xlfn.XLOOKUP($E6,raw_materials!$B:$B,raw_materials!B:B) -> GM | F6: =_xlfn.XLOOKUP($E6,raw_materials!$B:$B,raw_materials!C:C) -> All
A7: Bruschetta Alla Stracciatella | B7: =_xlfn.XLOOKUP(A7,[1]Table0!$A:$A,[1]Table0!$B:$B) -> Pizza 1 | C7: =_xlfn.XLOOKUP($E7,raw_materials!$B:$B,raw_materials!#REF!) -> Impasto Bruschetta | D7: =_xlfn.XLOOKUP($E7,raw_materials!$B:$B,raw_materials!A:A) -> 100 | E7: =_xlfn.XLOOKUP($E7,raw_materials!$B:$B,raw_materials!B:B) -> GM | F7: =_xlfn.XLOOKUP($E7,raw_materials!$B:$B,raw_materials!C:C) -> All
A8: Bruschetta Alla Nduja | B8: =_xlfn.XLOOKUP(A8,[1]Table0!$A:$A,[1]Table0!$B:$B) -> Pizza 1 | C8: =_xlfn.XLOOKUP($E8,raw_materials!$B:$B,raw_materials!#REF!) -> Impasto Bruschetta | D8: =_xlfn.XLOOKUP($E8,raw_materials!$B:$B,raw_materials!A:A) -> 100 | E8: =_xlfn.XLOOKUP($E8,raw_materials!$B:$B,raw_materials!B:B) -> GM | F8: =_xlfn.XLOOKUP($E8,raw_materials!$B:$B,raw_materials!C:C) -> All
A9: Bruschetta Con Pate' Di Olive | B9: =_xlfn.XLOOKUP(A9,[1]Table0!$A:$A,[1]Table0!$B:$B) -> Pizza 1 | C9: =_xlfn.XLOOKUP($E9,raw_materials!$B:$B,raw_materials!#REF!) -> Impasto Bruschetta | D9: =_xlfn.XLOOKUP($E9,raw_materials!$B:$B,raw_materials!A:A) -> 100 | E9: =_xlfn.XLOOKUP($E9,raw_materials!$B:$B,raw_materials!B:B) -> GM | F9: =_xlfn.XLOOKUP($E9,raw_materials!$B:$B,raw_materials!C:C) -> All
A10: Vellutata Di Zucca Con Funghi | B10: =_xlfn.XLOOKUP(A10,[1]Table0!$A:$A,[1]Table0!$B:$B) -> Italian 1 | C10: =_xlfn.XLOOKUP($E10,raw_materials!$B:$B,raw_materials!#REF!) -> Crema Di Zucca | D10: =_xlfn.XLOOKUP($E10,raw_materials!$B:$B,raw_materials!A:A) -> 200 | E10: =_xlfn.XLOOKUP($E10,raw_materials!$B:$B,raw_materials!B:B) -> GM | F10: =_xlfn.XLOOKUP($E10,raw_materials!$B:$B,raw_materials!C:C) -> All
A11: Minestrone Con Polpette | B11: =_xlfn.XLOOKUP(A11,[1]Table0!$A:$A,[1]Table0!$B:$B) -> Italian 1 | C11: =_xlfn.XLOOKUP($E11,raw_materials!$B:$B,raw_materials!#REF!) -> Minestrone | D11: =_xlfn.XLOOKUP($E11,raw_materials!$B:$B,raw_materials!A:A) -> 250 | E11: =_xlfn.XLOOKUP($E11,raw_materials!$B:$B,raw_materials!B:B) -> GM | F11: =_xlfn.XLOOKUP($E11,raw_materials!$B:$B,raw_materials!C:C) -> All
A12: Insalata Mista Con Mozzarella Salad | B12: =_xlfn.XLOOKUP(A12,[1]Table0!$A:$A,[1]Table0!$B:$B) -> Italian 1 | C12: =_xlfn.XLOOKUP($E12,raw_materials!$B:$B,raw_materials!#REF!) -> Kalamata Pitted Olives 3.6 Kg | D12: =_xlfn.XLOOKUP($E12,raw_materials!$B:$B,raw_materials!A:A) -> 15 | E12: =_xlfn.XLOOKUP($E12,raw_materials!$B:$B,raw_materials!B:B) -> GM | F12: =_xlfn.XLOOKUP($E12,raw_materials!$B:$B,raw_materials!C:C) -> All
A13: Insalata Mista Con Pollo Salad | B13: =_xlfn.XLOOKUP(A13,[1]Table0!$A:$A,[1]Table0!$B:$B) -> Italian 1 | C13: =_xlfn.XLOOKUP($E13,raw_materials!$B:$B,raw_materials!#REF!) -> Grill Chicken Italian | D13: =_xlfn.XLOOKUP($E13,raw_materials!$B:$B,raw_materials!A:A) -> 80 | E13: =_xlfn.XLOOKUP($E13,raw_materials!$B:$B,raw_materials!B:B) -> GM | F13: =_xlfn.XLOOKUP($E13,raw_materials!$B:$B,raw_materials!C:C) -> All
... A308: Caramelized Chicken Pizza Half | B308: =_xlfn.XLOOKUP(A308,[1]Table0!$A:$A,[1]Table0!$B:$B) -> Pizza 1 | C308: =_xlfn.XLOOKUP($E308,raw_materials!$B:$B,raw_materials!#REF!) -> Impasto Pizza | D308: =_xlfn.XLOOKUP($E308,raw_materials!$B:$B,raw_materials!A:A) -> 140 | E308: =_xlfn.XLOOKUP($E308,raw_materials!$B:$B,raw_materials!B:B) -> GM | F308: =_xlfn.XLOOKUP($E308,raw_materials!$B:$B,raw_materials!C:C) -> All
A309: Frittini Veg | B309: =_xlfn.XLOOKUP(A309,[1]Table0!$A:$A,[1]Table0!$B:$B) -> Italian 1
A310: Frittini Non Veg | B310: =_xlfn.XLOOKUP(A310,[1]Table0!$A:$A,[1]Table0!$B:$B) -> Italian 1
A311: Tagliere Di Formaggi | B311: =_xlfn.XLOOKUP(A311,[1]Table0!$A:$A,[1]Table0!$B:$B) -> Italian 1
A312: Tagliere Di Salumi | B312: =_xlfn.XLOOKUP(A312,[1]Table0!$A:$A,[1]Table0!$B:$B) -> Italian 1
A313: Bruschetta Alle Melanzane | B313: =_xlfn.XLOOKUP(A313,[1]Table0!$A:$A,[1]Table0!$B:$B) -> Pizza 1
A314: Bruschetta Alla Stracciatella | B314: =_xlfn.XLOOKUP(A314,[1]Table0!$A:$A,[1]Table0!$B:$B) -> Pizza 1
A315: Bruschetta Alla Nduja | B315: =_xlfn.XLOOKUP(A315,[1]Table0!$A:$A,[1]Table0!$B:$B) -> Pizza 1
A316: Bruschetta Con Pate' Di Olive | B316: =_xlfn.XLOOKUP(A316,[1]Table0!$A:$A,[1]Table0!$B:$B) -> Pizza 1
A317: Vellutata Di Zucca Con Funghi | B317: =_xlfn.XLOOKUP(A317,[1]Table0!$A:$A,[1]Table0!$B:$B) -> Italian 1
A318: Minestrone Con Polpette | B318: =_xlfn.XLOOKUP(A318,[1]Table0!$A:$A,[1]Table0!$B:$B) -> Italian 1
A319: Insalata Mista Con Mozzarella Salad | B319: =_xlfn.XLOOKUP(A319,[1]Table0!$A:$A,[1]Table0!$B:$B) -> Italian 1
A320: Insalata Mista Con Pollo Salad | B320: =_xlfn.XLOOKUP(A320,[1]Table0!$A:$A,[1]Table0!$B:$B) -> Italian 1
... A2457: Caramelized Chicken Pizza Half | B2457: =_xlfn.XLOOKUP(A2457,[1]Table0!$A:$A,[1]Table0!$B:$B) -> Pizza 1

Sheet worklog
A1: id | B1: Item | C1: orginal item name | D1: Qty. | E1: Total (₹) | F1: Items from recipe | G1: Department | H1: RawMaterial | I1: Qty | J1: Unit | K1: Area | L1: RawMaterial | M1: Qty | N1: Unit | O1: Area | P1: RawMaterial | Q1: Qty | R1: Unit | S1: Area | T1: RawMaterial | U1: Qty | V1: Unit | W1: Area | X1: RawMaterial | Y1: Qty | Z1: Unit | AA1: Area | AB1: RawMaterial | AC1: Qty | AD1: Unit | AE1: Area | AF1: RawMaterial | AG1: Qty | AH1: Unit | AI1: Area | AJ1: RawMaterial | AK1: Qty | AL1: Unit | AM1: Area | AN1: RawMaterial | AO1: Qty | AP1: Unit | AQ1: Area | AR1: RawMaterial | AS1: Qty | AT1: Unit | AU1: Area | AV1: RawMaterial | AW1: Qty | AX1: Unit | AY1: Area | AZ1: RawMaterial | BA1: Qty | BB1: Unit | BC1: Area | BD1: RawMaterial | BE1: Qty | BF1: Unit | BG1: Area | BH1: RawMaterial | BI1: Qty | BJ1: Unit | BK1: Area | BL1: RawMaterial | BM1: Qty | BN1: Unit | BO1: Area
A2: 1 | B2: Frittini Veg | C2: Frittini Veg | D2: 39 | E2: 12675 | F2: Frittini Veg | G2: =_xlfn.XLOOKUP(F2,[1]Table0!$A:$A,[1]Table0!$B:$B) -> Italian 1 | H2: =_xlfn.XLOOKUP($F2,raw_materials!$B:$B,raw_materials!D:D) -> Pittula | I2: =_xlfn.XLOOKUP($F2,raw_materials!$B:$B,raw_materials!E:E) -> 120 | J2: =_xlfn.XLOOKUP($F2,raw_materials!$B:$B,raw_materials!F:F) -> GM | K2: =_xlfn.XLOOKUP($F2,raw_materials!$B:$B,raw_materials!G:G) -> All | L2: =_xlfn.XLOOKUP($F2,raw_materials!$B:$B,raw_materials!H:H) -> Polpetta Di Melanzane | M2: =_xlfn.XLOOKUP($F2,raw_materials!$B:$B,raw_materials!I:I) -> 150 | N2: =_xlfn.XLOOKUP($F2,raw_materials!$B:$B,raw_materials!J:J) -> GM | O2: =_xlfn.XLOOKUP($F2,raw_materials!$B:$B,raw_materials!K:K) -> All | P2: =_xlfn.XLOOKUP($F2,raw_materials!$B:$B,raw_materials!L:L) -> Zucchini Green | Q2: =_xlfn.XLOOKUP($F2,raw_materials!$B:$B,raw_materials!M:M) -> 25 | R2: =_xlfn.XLOOKUP($F2,raw_materials!$B:$B,raw_materials!N:N) -> GM | S2: =_xlfn.XLOOKUP($F2,raw_materials!$B:$B,raw_materials!O:O) -> All | T2: =_xlfn.XLOOKUP($F2,raw_materials!$B:$B,raw_materials!P:P) -> Crema Di Cavolfiore | U2: =_xlfn.XLOOKUP($F2,raw_materials!$B:$B,raw_materials!Q:Q) -> 50 | V2: =_xlfn.XLOOKUP($F2,raw_materials!$B:$B,raw_materials!R:R) -> GM | W2: =_xlfn.XLOOKUP($F2,raw_materials!$B:$B,raw_materials!S:S) -> All | X2: =_xlfn.XLOOKUP($F2,raw_materials!$B:$B,raw_materials!T:T) -> Gazpacho Di Peperone | Y2: =_xlfn.XLOOKUP($F2,raw_materials!$B:$B,raw_materials!U:U) -> 50 | Z2: =_xlfn.XLOOKUP($F2,raw_materials!$B:$B,raw_materials!V:V) -> GM | AA2: =_xlfn.XLOOKUP($F2,raw_materials!$B:$B,raw_materials!W:W) -> All | AB2: =_xlfn.XLOOKUP($F2,raw_materials!$B:$B,raw_materials!X:X) -> Zucchini Yellow | AC2: =_xlfn.XLOOKUP($F2,raw_materials!$B:$B,raw_materials!Y:Y) -> 25 | AD2: =_xlfn.XLOOKUP($F2,raw_materials!$B:$B,raw_materials!Z:Z) -> GM | AE2: =_xlfn.XLOOKUP($F2,raw_materials!$B:$B,raw_materials!AA:AA) -> All | AF2: =_xlfn.XLOOKUP($F2,raw_materials!$B:$B,raw_materials!AB:AB) -> Eggplant | AG2: =_xlfn.XLOOKUP($F2,raw_materials!$B:$B,raw_materials!AC:AC) -> 50 | AH2: =_xlfn.XLOOKUP($F2,raw_materials!$B:$B,raw_materials!AD:AD) -> GM | AI2: =_xlfn.XLOOKUP($F2,raw_materials!$B:$B,raw_materials!AE:AE) -> All | AJ2: =_xlfn.XLOOKUP($F2,raw_materials!$B:$B,raw_materials!AF:AF) -> Capsicum Red | AK2: =_xlfn.XLOOKUP($F2,raw_materials!$B:$B,raw_materials!AG:AG) -> 30 | AL2: =_xlfn.XLOOKUP($F2,raw_materials!$B:$B,raw_materials!AH:AH) -> GM | AM2: =_xlfn.XLOOKUP($F2,raw_materials!$B:$B,raw_materials!AI:AI) -> All | AN2: =_xlfn.XLOOKUP($F2,raw_materials!$B:$B,raw_materials!AJ:AJ) -> Capsicum Yellow | AO2: =_xlfn.XLOOKUP($F2,raw_materials!$B:$B,raw_materials!AK:AK) -> 30 | AP2: =_xlfn.XLOOKUP($F2,raw_materials!$B:$B,raw_materials!AL:AL) -> GM | AQ2: =_xlfn.XLOOKUP($F2,raw_materials!$B:$B,raw_materials!AM:AM) -> All | AR2: =_xlfn.XLOOKUP($F2,raw_materials!$B:$B,raw_materials!AN:AN) -> Rava Sooji | AS2: =_xlfn.XLOOKUP($F2,raw_materials!$B:$B,raw_materials!AO:AO) -> 30 | AT2: =_xlfn.XLOOKUP($F2,raw_materials!$B:$B,raw_materials!AP:AP) -> GM | AU2: =_xlfn.XLOOKUP($F2,raw_materials!$B:$B,raw_materials!AQ:AQ) -> All | AV2: =_xlfn.XLOOKUP($F2,raw_materials!$B:$B,raw_materials!AR:AR) -> Table Salt | AW2: =_xlfn.XLOOKUP($F2,raw_materials!$B:$B,raw_materials!AS:AS) -> 5 | AX2: =_xlfn.XLOOKUP($F2,raw_materials!$B:$B,raw_materials!AT:AT) -> GM | AY2: =_xlfn.XLOOKUP($F2,raw_materials!$B:$B,raw_materials!AU:AU) -> All | AZ2: =_xlfn.XLOOKUP($F2,raw_materials!$B:$B,raw_materials!AV:AV) -> 0 | BA2: =_xlfn.XLOOKUP($F2,raw_materials!$B:$B,raw_materials!AW:AW) -> 0 | BB2: =_xlfn.XLOOKUP($F2,raw_materials!$B:$B,raw_materials!AX:AX) -> 0 | BC2: =_xlfn.XLOOKUP($F2,raw_materials!$B:$B,raw_materials!AY:AY) -> 0 | BD2: =_xlfn.XLOOKUP($F2,raw_materials!$B:$B,raw_materials!AZ:AZ) -> 0 | BE2: =_xlfn.XLOOKUP($F2,raw_materials!$B:$B,raw_materials!BA:BA) -> 0 | BF2: =_xlfn.XLOOKUP($F2,raw_materials!$B:$B,raw_materials!BB:BB) -> 0 | BG2: =_xlfn.XLOOKUP($F2,raw_materials!$B:$B,raw_materials!BC:BC) -> 0 | BH2: =_xlfn.XLOOKUP($F2,raw_materials!$B:$B,raw_materials!BD:BD) -> 0 | BI2: =_xlfn.XLOOKUP($F2,raw_materials!$B:$B,raw_materials!BE:BE) -> 0 | BJ2: =_xlfn.XLOOKUP($F2,raw_materials!$B:$B,raw_materials!BF:BF) -> 0 | BK2: =_xlfn.XLOOKUP($F2,raw_materials!$B:$B,raw_materials!BG:BG) -> 0 | BL2: =_xlfn.XLOOKUP($F2,raw_materials!$B:$B,raw_materials!BH:BH) -> 0 | BM2: =_xlfn.XLOOKUP($F2,raw_materials!$B:$B,raw_materials!BI:BI) -> 0 | BN2: =_xlfn.XLOOKUP($F2,raw_materials!$B:$B,raw_materials!BJ:BJ) -> 0 | BO2: =_xlfn.XLOOKUP($F2,raw_materials!$B:$B,raw_materials!BK:BK) -> 0
A3: 2 | B3: Frittini Non Veg | C3: Frittini Non Veg | D3: 21 | E3: 12075 | F3: Frittini Non Veg | G3: =_xlfn.XLOOKUP(F3,[1]Table0!$A:$A,[1]Table0!$B:$B) -> Italian 1 | H3: =_xlfn.XLOOKUP($F3,raw_materials!$B:$B,raw_materials!D:D) -> Crocchette Di Patate | I3: =_xlfn.XLOOKUP($F3,raw_materials!$B:$B,raw_materials!E:E) -> 150 | J3: =_xlfn.XLOOKUP($F3,raw_materials!$B:$B,raw_materials!F:F) -> GM | K3: =_xlfn.XLOOKUP($F3,raw_materials!$B:$B,raw_materials!G:G) -> All | L3: =_xlfn.XLOOKUP($F3,raw_materials!$B:$B,raw_materials!H:H) -> Arancino | M3: =_xlfn.XLOOKUP($F3,raw_materials!$B:$B,raw_materials!I:I) -> 150 | N3: =_xlfn.XLOOKUP($F3,raw_materials!$B:$B,raw_materials!J:J) -> GM | O3: =_xlfn.XLOOKUP($F3,raw_materials!$B:$B,raw_materials!K:K) -> All | P3: =_xlfn.XLOOKUP($F3,raw_materials!$B:$B,raw_materials!L:L) -> Polpette Di Manzo | Q3: =_xlfn.XLOOKUP($F3,raw_materials!$B:$B,raw_materials!M:M) -> 150 | R3: =_xlfn.XLOOKUP($F3,raw_materials!$B:$B,raw_materials!N:N) -> GM | S3: =_xlfn.XLOOKUP($F3,raw_materials!$B:$B,raw_materials!O:O) -> All | T3: =_xlfn.XLOOKUP($F3,raw_materials!$B:$B,raw_materials!P:P) -> Gazpacho Di Peperone | U3: =_xlfn.XLOOKUP($F3,raw_materials!$B:$B,raw_materials!Q:Q) -> 50 | V3: =_xlfn.XLOOKUP($F3,raw_materials!$B:$B,raw_materials!R:R) -> GM | W3: =_xlfn.XLOOKUP($F3,raw_materials!$B:$B,raw_materials!S:S) -> All | X3: =_xlfn.XLOOKUP($F3,raw_materials!$B:$B,raw_materials!T:T) -> Crema Di Cavolfiore | Y3: =_xlfn.XLOOKUP($F3,raw_materials!$B:$B,raw_materials!U:U) -> 50 | Z3: =_xlfn.XLOOKUP($F3,raw_materials!$B:$B,raw_materials!V:V) -> GM | AA3: =_xlfn.XLOOKUP($F3,raw_materials!$B:$B,raw_materials!W:W) -> All | AB3: =_xlfn.XLOOKUP($F3,raw_materials!$B:$B,raw_materials!X:X) -> Potato Btr | AC3: =_xlfn.XLOOKUP($F3,raw_materials!$B:$B,raw_materials!Y:Y) -> 50 | AD3: =_xlfn.XLOOKUP($F3,raw_materials!$B:$B,raw_materials!Z:Z) -> GM | AE3: =_xlfn.XLOOKUP($F3,raw_materials!$B:$B,raw_materials!AA:AA) -> All | AF3: =_xlfn.XLOOKUP($F3,raw_materials!$B:$B,raw_materials!AB:AB) -> 0 | AG3: =_xlfn.XLOOKUP($F3,raw_materials!$B:$B,raw_materials!AC:AC) -> 0 | AH3: =_xlfn.XLOOKUP($F3,raw_materials!$B:$B,raw_materials!AD:AD) -> 0 | AI3: =_xlfn.XLOOKUP($F3,raw_materials!$B:$B,raw_materials!AE:AE) -> 0 | AJ3: =_xlfn.XLOOKUP($F3,raw_materials!$B:$B,raw_materials!AF:AF) -> 0 | AK3: =_xlfn.XLOOKUP($F3,raw_materials!$B:$B,raw_materials!AG:AG) -> 0 | AL3: =_xlfn.XLOOKUP($F3,raw_materials!$B:$B,raw_materials!AH:AH) -> 0 | AM3: =_xlfn.XLOOKUP($F3,raw_materials!$B:$B,raw_materials!AI:AI) -> 0 | AN3: =_xlfn.XLOOKUP($F3,raw_materials!$B:$B,raw_materials!AJ:AJ) -> 0 | AO3: =_xlfn.XLOOKUP($F3,raw_materials!$B:$B,raw_materials!AK:AK) -> 0 | AP3: =_xlfn.XLOOKUP($F3,raw_materials!$B:$B,raw_materials!AL:AL) -> 0 | AQ3: =_xlfn.XLOOKUP($F3,raw_materials!$B:$B,raw_materials!AM:AM) -> 0 | AR3: =_xlfn.XLOOKUP($F3,raw_materials!$B:$B,raw_materials!AN:AN) -> 0 | AS3: =_xlfn.XLOOKUP($F3,raw_materials!$B:$B,raw_materials!AO:AO) -> 0 | AT3: =_xlfn.XLOOKUP($F3,raw_materials!$B:$B,raw_materials!AP:AP) -> 0 | AU3: =_xlfn.XLOOKUP($F3,raw_materials!$B:$B,raw_materials!AQ:AQ) -> 0 | AV3: =_xlfn.XLOOKUP($F3,raw_materials!$B:$B,raw_materials!AR:AR) -> 0 | AW3: =_xlfn.XLOOKUP($F3,raw_materials!$B:$B,raw_materials!AS:AS) -> 0 | AX3: =_xlfn.XLOOKUP($F3,raw_materials!$B:$B,raw_materials!AT:AT) -> 0 | AY3: =_xlfn.XLOOKUP($F3,raw_materials!$B:$B,raw_materials!AU:AU) -> 0 | AZ3: =_xlfn.XLOOKUP($F3,raw_materials!$B:$B,raw_materials!AV:AV) -> 0 | BA3: =_xlfn.XLOOKUP($F3,raw_materials!$B:$B,raw_materials!AW:AW) -> 0 | BB3: =_xlfn.XLOOKUP($F3,raw_materials!$B:$B,raw_materials!AX:AX) -> 0 | BC3: =_xlfn.XLOOKUP($F3,raw_materials!$B:$B,raw_materials!AY:AY) -> 0 | BD3: =_xlfn.XLOOKUP($F3,raw_materials!$B:$B,raw_materials!AZ:AZ) -> 0 | BE3: =_xlfn.XLOOKUP($F3,raw_materials!$B:$B,raw_materials!BA:BA) -> 0 | BF3: =_xlfn.XLOOKUP($F3,raw_materials!$B:$B,raw_materials!BB:BB) -> 0 | BG3: =_xlfn.XLOOKUP($F3,raw_materials!$B:$B,raw_materials!BC:BC) -> 0 | BH3: =_xlfn.XLOOKUP($F3,raw_materials!$B:$B,raw_materials!BD:BD) -> 0 | BI3: =_xlfn.XLOOKUP($F3,raw_materials!$B:$B,raw_materials!BE:BE) -> 0 | BJ3: =_xlfn.XLOOKUP($F3,raw_materials!$B:$B,raw_materials!BF:BF) -> 0 | BK3: =_xlfn.XLOOKUP($F3,raw_materials!$B:$B,raw_materials!BG:BG) -> 0 | BL3: =_xlfn.XLOOKUP($F3,raw_materials!$B:$B,raw_materials!BH:BH) -> 0 | BM3: =_xlfn.XLOOKUP($F3,raw_materials!$B:$B,raw_materials!BI:BI) -> 0 | BN3: =_xlfn.XLOOKUP($F3,raw_materials!$B:$B,raw_materials!BJ:BJ) -> 0 | BO3: =_xlfn.XLOOKUP($F3,raw_materials!$B:$B,raw_materials!BK:BK) -> 0
A4: 3 | B4: Tagliere Di Formaggi | C4: Tagliere Di Formaggi | D4: 20 | E4: 18900 | F4: Tagliere Di Formaggi | G4: =_xlfn.XLOOKUP(F4,[1]Table0!$A:$A,[1]Table0!$B:$B) -> Italian 1 | H4: =_xlfn.XLOOKUP($F4,raw_materials!$B:$B,raw_materials!D:D) -> Grana Padano | I4: =_xlfn.XLOOKUP($F4,raw_materials!$B:$B,raw_materials!E:E) -> 30 | J4: =_xlfn.XLOOKUP($F4,raw_materials!$B:$B,raw_materials!F:F) -> GM | K4: =_xlfn.XLOOKUP($F4,raw_materials!$B:$B,raw_materials!G:G) -> All | L4: =_xlfn.XLOOKUP($F4,raw_materials!$B:$B,raw_materials!H:H) -> Provolone Dolce | M4: =_xlfn.XLOOKUP($F4,raw_materials!$B:$B,raw_materials!I:I) -> 30 | N4: =_xlfn.XLOOKUP($F4,raw_materials!$B:$B,raw_materials!J:J) -> GM | O4: =_xlfn.XLOOKUP($F4,raw_materials!$B:$B,raw_materials!K:K) -> All | P4: =_xlfn.XLOOKUP($F4,raw_materials!$B:$B,raw_materials!L:L) -> Marmellata Di Cipolla | Q4: =_xlfn.XLOOKUP($F4,raw_materials!$B:$B,raw_materials!M:M) -> 40 | R4: =_xlfn.XLOOKUP($F4,raw_materials!$B:$B,raw_materials!N:N) -> GM | S4: =_xlfn.XLOOKUP($F4,raw_materials!$B:$B,raw_materials!O:O) -> All | T4: =_xlfn.XLOOKUP($F4,raw_materials!$B:$B,raw_materials!P:P) -> Big Burrata | U4: =_xlfn.XLOOKUP($F4,raw_materials!$B:$B,raw_materials!Q:Q) -> 125 | V4: =_xlfn.XLOOKUP($F4,raw_materials!$B:$B,raw_materials!R:R) -> GM | W4: =_xlfn.XLOOKUP($F4,raw_materials!$B:$B,raw_materials!S:S) -> All | X4: =_xlfn.XLOOKUP($F4,raw_materials!$B:$B,raw_materials!T:T) -> Olive Green Pitted | Y4: =_xlfn.XLOOKUP($F4,raw_materials!$B:$B,raw_materials!U:U) -> 10 | Z4: =_xlfn.XLOOKUP($F4,raw_materials!$B:$B,raw_materials!V:V) -> GM | AA4: =_xlfn.XLOOKUP($F4,raw_materials!$B:$B,raw_materials!W:W) -> All | AB4: =_xlfn.XLOOKUP($F4,raw_materials!$B:$B,raw_materials!X:X) -> Black Olives Sliced | AC4: =_xlfn.XLOOKUP($F4,raw_materials!$B:$B,raw_materials!Y:Y) -> 10 | AD4: =_xlfn.XLOOKUP($F4,raw_materials!$B:$B,raw_materials!Z:Z) -> GM | AE4: =_xlfn.XLOOKUP($F4,raw_materials!$B:$B,raw_materials!AA:AA) -> All | AF4: =_xlfn.XLOOKUP($F4,raw_materials!$B:$B,raw_materials!AB:AB) -> Kalamata Pitted Olives 3.6 Kg | AG4: =_xlfn.XLOOKUP($F4,raw_materials!$B:$B,raw_materials!AC:AC) -> 10 | AH4: =_xlfn.XLOOKUP($F4,raw_materials!$B:$B,raw_materials!AD:AD) -> GM | AI4: =_xlfn.XLOOKUP($F4,raw_materials!$B:$B,raw_materials!AE:AE) -> All | AJ4: =_xlfn.XLOOKUP($F4,raw_materials!$B:$B,raw_materials!AF:AF) -> Rocket Lettuce | AK4: =_xlfn.XLOOKUP($F4,raw_materials!$B:$B,raw_materials!AG:AG) -> 10 | AL4: =_xlfn.XLOOKUP($F4,raw_materials!$B:$B,raw_materials!AH:AH) -> GM | AM4: =_xlfn.XLOOKUP($F4,raw_materials!$B:$B,raw_materials!AI:AI) -> All | AN4: =_xlfn.XLOOKUP($F4,raw_materials!$B:$B,raw_materials!AJ:AJ) -> Tomato Cherry | AO4: =_xlfn.XLOOKUP($F4,raw_materials!$B:$B,raw_materials!AK:AK) -> 10 | AP4: =_xlfn.XLOOKUP($F4,raw_materials!$B:$B,raw_materials!AL:AL) -> GM | AQ4: =_xlfn.XLOOKUP($F4,raw_materials!$B:$B,raw_materials!AM:AM) -> All | AR4: =_xlfn.XLOOKUP($F4,raw_materials!$B:$B,raw_materials!AN:AN) -> Smoked Scamorza | AS4: =_xlfn.XLOOKUP($F4,raw_materials!$B:$B,raw_materials!AO:AO) -> 30 | AT4: =_xlfn.XLOOKUP($F4,raw_materials!$B:$B,raw_materials!AP:AP) -> GM | AU4: =_xlfn.XLOOKUP($F4,raw_materials!$B:$B,raw_materials!AQ:AQ) -> All | AV4: =_xlfn.XLOOKUP($F4,raw_materials!$B:$B,raw_materials!AR:AR) -> Grissini | AW4: =_xlfn.XLOOKUP($F4,raw_materials!$B:$B,raw_materials!AS:AS) -> 30 | AX4: =_xlfn.XLOOKUP($F4,raw_materials!$B:$B,raw_materials!AT:AT) -> GM | AY4: =_xlfn.XLOOKUP($F4,raw_materials!$B:$B,raw_materials!AU:AU) -> All | AZ4: =_xlfn.XLOOKUP($F4,raw_materials!$B:$B,raw_materials!AV:AV) -> 0 | BA4: =_xlfn.XLOOKUP($F4,raw_materials!$B:$B,raw_materials!AW:AW) -> 0 | BB4: =_xlfn.XLOOKUP($F4,raw_materials!$B:$B,raw_materials!AX:AX) -> 0 | BC4: =_xlfn.XLOOKUP($F4,raw_materials!$B:$B,raw_materials!AY:AY) -> 0 | BD4: =_xlfn.XLOOKUP($F4,raw_materials!$B:$B,raw_materials!AZ:AZ) -> 0 | BE4: =_xlfn.XLOOKUP($F4,raw_materials!$B:$B,raw_materials!BA:BA) -> 0 | BF4: =_xlfn.XLOOKUP($F4,raw_materials!$B:$B,raw_materials!BB:BB) -> 0 | BG4: =_xlfn.XLOOKUP($F4,raw_materials!$B:$B,raw_materials!BC:BC) -> 0 | BH4: =_xlfn.XLOOKUP($F4,raw_materials!$B:$B,raw_materials!BD:BD) -> 0 | BI4: =_xlfn.XLOOKUP($F4,raw_materials!$B:$B,raw_materials!BE:BE) -> 0 | BJ4: =_xlfn.XLOOKUP($F4,raw_materials!$B:$B,raw_materials!BF:BF) -> 0 | BK4: =_xlfn.XLOOKUP($F4,raw_materials!$B:$B,raw_materials!BG:BG) -> 0 | BL4: =_xlfn.XLOOKUP($F4,raw_materials!$B:$B,raw_materials!BH:BH) -> 0 | BM4: =_xlfn.XLOOKUP($F4,raw_materials!$B:$B,raw_materials!BI:BI) -> 0 | BN4: =_xlfn.XLOOKUP($F4,raw_materials!$B:$B,raw_materials!BJ:BJ) -> 0 | BO4: =_xlfn.XLOOKUP($F4,raw_materials!$B:$B,raw_materials!BK:BK) -> 0
A5: 4 | B5: Tagliere Di Salumi | C5: Tagliere Di Salumi | D5: 34 | E5: 32130 | F5: Tagliere Di Salumi | G5: =_xlfn.XLOOKUP(F5,[1]Table0!$A:$A,[1]Table0!$B:$B) -> Italian 1 | H5: =_xlfn.XLOOKUP($F5,raw_materials!$B:$B,raw_materials!D:D) -> Cooked Ham | I5: =_xlfn.XLOOKUP($F5,raw_materials!$B:$B,raw_materials!E:E) -> 30 | J5: =_xlfn.XLOOKUP($F5,raw_materials!$B:$B,raw_materials!F:F) -> GM | K5: =_xlfn.XLOOKUP($F5,raw_materials!$B:$B,raw_materials!G:G) -> All | L5: =_xlfn.XLOOKUP($F5,raw_materials!$B:$B,raw_materials!H:H) -> Coppa | M5: =_xlfn.XLOOKUP($F5,raw_materials!$B:$B,raw_materials!I:I) -> 30 | N5: =_xlfn.XLOOKUP($F5,raw_materials!$B:$B,raw_materials!J:J) -> GM | O5: =_xlfn.XLOOKUP($F5,raw_materials!$B:$B,raw_materials!K:K) -> All | P5: =_xlfn.XLOOKUP($F5,raw_materials!$B:$B,raw_materials!L:L) -> Mortadella Bologna | Q5: =_xlfn.XLOOKUP($F5,raw_materials!$B:$B,raw_materials!M:M) -> 30 | R5: =_xlfn.XLOOKUP($F5,raw_materials!$B:$B,raw_materials!N:N) -> GM | S5: =_xlfn.XLOOKUP($F5,raw_materials!$B:$B,raw_materials!O:O) -> All | T5: =_xlfn.XLOOKUP($F5,raw_materials!$B:$B,raw_materials!P:P) -> Spianata Calabrese | U5: =_xlfn.XLOOKUP($F5,raw_materials!$B:$B,raw_materials!Q:Q) -> 30 | V5: =_xlfn.XLOOKUP($F5,raw_materials!$B:$B,raw_materials!R:R) -> GM | W5: =_xlfn.XLOOKUP($F5,raw_materials!$B:$B,raw_materials!S:S) -> All | X5: =_xlfn.XLOOKUP($F5,raw_materials!$B:$B,raw_materials!T:T) -> Salami Milano | Y5: =_xlfn.XLOOKUP($F5,raw_materials!$B:$B,raw_materials!U:U) -> 30 | Z5: =_xlfn.XLOOKUP($F5,raw_materials!$B:$B,raw_materials!V:V) -> GM | AA5: =_xlfn.XLOOKUP($F5,raw_materials!$B:$B,raw_materials!W:W) -> All | AB5: =_xlfn.XLOOKUP($F5,raw_materials!$B:$B,raw_materials!X:X) -> Black Olives Sliced | AC5: =_xlfn.XLOOKUP($F5,raw_materials!$B:$B,raw_materials!Y:Y) -> 10 | AD5: =_xlfn.XLOOKUP($F5,raw_materials!$B:$B,raw_materials!Z:Z) -> GM | AE5: =_xlfn.XLOOKUP($F5,raw_materials!$B:$B,raw_materials!AA:AA) -> All | AF5: =_xlfn.XLOOKUP($F5,raw_materials!$B:$B,raw_materials!AB:AB) -> Olive Green Pitted | AG5: =_xlfn.XLOOKUP($F5,raw_materials!$B:$B,raw_materials!AC:AC) -> 10 | AH5: =_xlfn.XLOOKUP($F5,raw_materials!$B:$B,raw_materials!AD:AD) -> GM | AI5: =_xlfn.XLOOKUP($F5,raw_materials!$B:$B,raw_materials!AE:AE) -> All | AJ5: =_xlfn.XLOOKUP($F5,raw_materials!$B:$B,raw_materials!AF:AF) -> Grissini | AK5: =_xlfn.XLOOKUP($F5,raw_materials!$B:$B,raw_materials!AG:AG) -> 30 | AL5: =_xlfn.XLOOKUP($F5,raw_materials!$B:$B,raw_materials!AH:AH) -> GM | AM5: =_xlfn.XLOOKUP($F5,raw_materials!$B:$B,raw_materials!AI:AI) -> All | AN5: =_xlfn.XLOOKUP($F5,raw_materials!$B:$B,raw_materials!AJ:AJ) -> Prosciutto Crudo Parma | AO5: =_xlfn.XLOOKUP($F5,raw_materials!$B:$B,raw_materials!AK:AK) -> 30 | AP5: =_xlfn.XLOOKUP($F5,raw_materials!$B:$B,raw_materials!AL:AL) -> GM | AQ5: =_xlfn.XLOOKUP($F5,raw_materials!$B:$B,raw_materials!AM:AM) -> All | AR5: =_xlfn.XLOOKUP($F5,raw_materials!$B:$B,raw_materials!AN:AN) -> Marmellata Di Cipolla | AS5: =_xlfn.XLOOKUP($F5,raw_materials!$B:$B,raw_materials!AO:AO) -> 40 | AT5: =_xlfn.XLOOKUP($F5,raw_materials!$B:$B,raw_materials!AP:AP) -> GM | AU5: =_xlfn.XLOOKUP($F5,raw_materials!$B:$B,raw_materials!AQ:AQ) -> All | AV5: =_xlfn.XLOOKUP($F5,raw_materials!$B:$B,raw_materials!AR:AR) -> Kalamata Pitted Olives 3.6 Kg | AW5: =_xlfn.XLOOKUP($F5,raw_materials!$B:$B,raw_materials!AS:AS) -> 10 | AX5: =_xlfn.XLOOKUP($F5,raw_materials!$B:$B,raw_materials!AT:AT) -> GM | AY5: =_xlfn.XLOOKUP($F5,raw_materials!$B:$B,raw_materials!AU:AU) -> All | AZ5: =_xlfn.XLOOKUP($F5,raw_materials!$B:$B,raw_materials!AV:AV) -> 0 | BA5: =_xlfn.XLOOKUP($F5,raw_materials!$B:$B,raw_materials!AW:AW) -> 0 | BB5: =_xlfn.XLOOKUP($F5,raw_materials!$B:$B,raw_materials!AX:AX) -> 0 | BC5: =_xlfn.XLOOKUP($F5,raw_materials!$B:$B,raw_materials!AY:AY) -> 0 | BD5: =_xlfn.XLOOKUP($F5,raw_materials!$B:$B,raw_materials!AZ:AZ) -> 0 | BE5: =_xlfn.XLOOKUP($F5,raw_materials!$B:$B,raw_materials!BA:BA) -> 0 | BF5: =_xlfn.XLOOKUP($F5,raw_materials!$B:$B,raw_materials!BB:BB) -> 0 | BG5: =_xlfn.XLOOKUP($F5,raw_materials!$B:$B,raw_materials!BC:BC) -> 0 | BH5: =_xlfn.XLOOKUP($F5,raw_materials!$B:$B,raw_materials!BD:BD) -> 0 | BI5: =_xlfn.XLOOKUP($F5,raw_materials!$B:$B,raw_materials!BE:BE) -> 0 | BJ5: =_xlfn.XLOOKUP($F5,raw_materials!$B:$B,raw_materials!BF:BF) -> 0 | BK5: =_xlfn.XLOOKUP($F5,raw_materials!$B:$B,raw_materials!BG:BG) -> 0 | BL5: =_xlfn.XLOOKUP($F5,raw_materials!$B:$B,raw_materials!BH:BH) -> 0 | BM5: =_xlfn.XLOOKUP($F5,raw_materials!$B:$B,raw_materials!BI:BI) -> 0 | BN5: =_xlfn.XLOOKUP($F5,raw_materials!$B:$B,raw_materials!BJ:BJ) -> 0 | BO5: =_xlfn.XLOOKUP($F5,raw_materials!$B:$B,raw_materials!BK:BK) -> 0
A6: 5 | B6: Bruschetta Alle Melanzane | C6: Bruschetta Alle Melanzane | D6: 18 | E6: 5310 | F6: Bruschetta Alle Melanzane | G6: =_xlfn.XLOOKUP(F6,[1]Table0!$A:$A,[1]Table0!$B:$B) -> Pizza 1 | H6: =_xlfn.XLOOKUP($F6,raw_materials!$B:$B,raw_materials!D:D) -> Impasto Bruschetta | I6: =_xlfn.XLOOKUP($F6,raw_materials!$B:$B,raw_materials!E:E) -> 100 | J6: =_xlfn.XLOOKUP($F6,raw_materials!$B:$B,raw_materials!F:F) -> GM | K6: =_xlfn.XLOOKUP($F6,raw_materials!$B:$B,raw_materials!G:G) -> All | L6: =_xlfn.XLOOKUP($F6,raw_materials!$B:$B,raw_materials!H:H) -> Roasted Brinjal Cream | M6: =_xlfn.XLOOKUP($F6,raw_materials!$B:$B,raw_materials!I:I) -> 50 | N6: =_xlfn.XLOOKUP($F6,raw_materials!$B:$B,raw_materials!J:J) -> GM | O6: =_xlfn.XLOOKUP($F6,raw_materials!$B:$B,raw_materials!K:K) -> All | P6: =_xlfn.XLOOKUP($F6,raw_materials!$B:$B,raw_materials!L:L) -> Roasted Cherry Tomato | Q6: =_xlfn.XLOOKUP($F6,raw_materials!$B:$B,raw_materials!M:M) -> 40 | R6: =_xlfn.XLOOKUP($F6,raw_materials!$B:$B,raw_materials!N:N) -> GM | S6: =_xlfn.XLOOKUP($F6,raw_materials!$B:$B,raw_materials!O:O) -> All | T6: =_xlfn.XLOOKUP($F6,raw_materials!$B:$B,raw_materials!P:P) -> Grana Padano | U6: =_xlfn.XLOOKUP($F6,raw_materials!$B:$B,raw_materials!Q:Q) -> 25 | V6: =_xlfn.XLOOKUP($F6,raw_materials!$B:$B,raw_materials!R:R) -> GM | W6: =_xlfn.XLOOKUP($F6,raw_materials!$B:$B,raw_materials!S:S) -> All | X6: =_xlfn.XLOOKUP($F6,raw_materials!$B:$B,raw_materials!T:T) -> 0 | Y6: =_xlfn.XLOOKUP($F6,raw_materials!$B:$B,raw_materials!U:U) -> 0 | Z6: =_xlfn.XLOOKUP($F6,raw_materials!$B:$B,raw_materials!V:V) -> 0 | AA6: =_xlfn.XLOOKUP($F6,raw_materials!$B:$B,raw_materials!W:W) -> 0 | AB6: =_xlfn.XLOOKUP($F6,raw_materials!$B:$B,raw_materials!X:X) -> 0 | AC6: =_xlfn.XLOOKUP($F6,raw_materials!$B:$B,raw_materials!Y:Y) -> 0 | AD6: =_xlfn.XLOOKUP($F6,raw_materials!$B:$B,raw_materials!Z:Z) -> 0 | AE6: =_xlfn.XLOOKUP($F6,raw_materials!$B:$B,raw_materials!AA:AA) -> 0 | AF6: =_xlfn.XLOOKUP($F6,raw_materials!$B:$B,raw_materials!AB:AB) -> 0 | AG6: =_xlfn.XLOOKUP($F6,raw_materials!$B:$B,raw_materials!AC:AC) -> 0 | AH6: =_xlfn.XLOOKUP($F6,raw_materials!$B:$B,raw_materials!AD:AD) -> 0 | AI6: =_xlfn.XLOOKUP($F6,raw_materials!$B:$B,raw_materials!AE:AE) -> 0 | AJ6: =_xlfn.XLOOKUP($F6,raw_materials!$B:$B,raw_materials!AF:AF) -> 0 | AK6: =_xlfn.XLOOKUP($F6,raw_materials!$B:$B,raw_materials!AG:AG) -> 0 | AL6: =_xlfn.XLOOKUP($F6,raw_materials!$B:$B,raw_materials!AH:AH) -> 0 | AM6: =_xlfn.XLOOKUP($F6,raw_materials!$B:$B,raw_materials!AI:AI) -> 0 | AN6: =_xlfn.XLOOKUP($F6,raw_materials!$B:$B,raw_materials!AJ:AJ) -> 0 | AO6: =_xlfn.XLOOKUP($F6,raw_materials!$B:$B,raw_materials!AK:AK) -> 0 | AP6: =_xlfn.XLOOKUP($F6,raw_materials!$B:$B,raw_materials!AL:AL) -> 0 | AQ6: =_xlfn.XLOOKUP($F6,raw_materials!$B:$B,raw_materials!AM:AM) -> 0 | AR6: =_xlfn.XLOOKUP($F6,raw_materials!$B:$B,raw_materials!AN:AN) -> 0 | AS6: =_xlfn.XLOOKUP($F6,raw_materials!$B:$B,raw_materials!AO:AO) -> 0 | AT6: =_xlfn.XLOOKUP($F6,raw_materials!$B:$B,raw_materials!AP:AP) -> 0 | AU6: =_xlfn.XLOOKUP($F6,raw_materials!$B:$B,raw_materials!AQ:AQ) -> 0 | AV6: =_xlfn.XLOOKUP($F6,raw_materials!$B:$B,raw_materials!AR:AR) -> 0 | AW6: =_xlfn.XLOOKUP($F6,raw_materials!$B:$B,raw_materials!AS:AS) -> 0 | AX6: =_xlfn.XLOOKUP($F6,raw_materials!$B:$B,raw_materials!AT:AT) -> 0 | AY6: =_xlfn.XLOOKUP($F6,raw_materials!$B:$B,raw_materials!AU:AU) -> 0 | AZ6: =_xlfn.XLOOKUP($F6,raw_materials!$B:$B,raw_materials!AV:AV) -> 0 | BA6: =_xlfn.XLOOKUP($F6,raw_materials!$B:$B,raw_materials!AW:AW) -> 0 | BB6: =_xlfn.XLOOKUP($F6,raw_materials!$B:$B,raw_materials!AX:AX) -> 0 | BC6: =_xlfn.XLOOKUP($F6,raw_materials!$B:$B,raw_materials!AY:AY) -> 0 | BD6: =_xlfn.XLOOKUP($F6,raw_materials!$B:$B,raw_materials!AZ:AZ) -> 0 | BE6: =_xlfn.XLOOKUP($F6,raw_materials!$B:$B,raw_materials!BA:BA) -> 0 | BF6: =_xlfn.XLOOKUP($F6,raw_materials!$B:$B,raw_materials!BB:BB) -> 0 | BG6: =_xlfn.XLOOKUP($F6,raw_materials!$B:$B,raw_materials!BC:BC) -> 0 | BH6: =_xlfn.XLOOKUP($F6,raw_materials!$B:$B,raw_materials!BD:BD) -> 0 | BI6: =_xlfn.XLOOKUP($F6,raw_materials!$B:$B,raw_materials!BE:BE) -> 0 | BJ6: =_xlfn.XLOOKUP($F6,raw_materials!$B:$B,raw_materials!BF:BF) -> 0 | BK6: =_xlfn.XLOOKUP($F6,raw_materials!$B:$B,raw_materials!BG:BG) -> 0 | BL6: =_xlfn.XLOOKUP($F6,raw_materials!$B:$B,raw_materials!BH:BH) -> 0 | BM6: =_xlfn.XLOOKUP($F6,raw_materials!$B:$B,raw_materials!BI:BI) -> 0 | BN6: =_xlfn.XLOOKUP($F6,raw_materials!$B:$B,raw_materials!BJ:BJ) -> 0 | BO6: =_xlfn.XLOOKUP($F6,raw_materials!$B:$B,raw_materials!BK:BK) -> 0
A7: 6 | B7: Bruschetta Alla Stracciatella | C7: Bruschetta Alla Stracciatella | D7: 67 | E7: 23450 | F7: Bruschetta Alla Stracciatella | G7: =_xlfn.XLOOKUP(F7,[1]Table0!$A:$A,[1]Table0!$B:$B) -> Pizza 1 | H7: =_xlfn.XLOOKUP($F7,raw_materials!$B:$B,raw_materials!D:D) -> Impasto Bruschetta | I7: =_xlfn.XLOOKUP($F7,raw_materials!$B:$B,raw_materials!E:E) -> 100 | J7: =_xlfn.XLOOKUP($F7,raw_materials!$B:$B,raw_materials!F:F) -> GM | K7: =_xlfn.XLOOKUP($F7,raw_materials!$B:$B,raw_materials!G:G) -> All | L7: =_xlfn.XLOOKUP($F7,raw_materials!$B:$B,raw_materials!H:H) -> Stracciatella | M7: =_xlfn.XLOOKUP($F7,raw_materials!$B:$B,raw_materials!I:I) -> 50 | N7: =_xlfn.XLOOKUP($F7,raw_materials!$B:$B,raw_materials!J:J) -> GM | O7: =_xlfn.XLOOKUP($F7,raw_materials!$B:$B,raw_materials!K:K) -> All | P7: =_xlfn.XLOOKUP($F7,raw_materials!$B:$B,raw_materials!L:L) -> Roasted Cherry Tomato | Q7: =_xlfn.XLOOKUP($F7,raw_materials!$B:$B,raw_materials!M:M) -> 40 | R7: =_xlfn.XLOOKUP($F7,raw_materials!$B:$B,raw_materials!N:N) -> GM | S7: =_xlfn.XLOOKUP($F7,raw_materials!$B:$B,raw_materials!O:O) -> All | T7: =_xlfn.XLOOKUP($F7,raw_materials!$B:$B,raw_materials!P:P) -> Basil Leaves | U7: =_xlfn.XLOOKUP($F7,raw_materials!$B:$B,raw_materials!Q:Q) -> 10 | V7: =_xlfn.XLOOKUP($F7,raw_materials!$B:$B,raw_materials!R:R) -> GM | W7: =_xlfn.XLOOKUP($F7,raw_materials!$B:$B,raw_materials!S:S) -> All | X7: =_xlfn.XLOOKUP($F7,raw_materials!$B:$B,raw_materials!T:T) -> 0 | Y7: =_xlfn.XLOOKUP($F7,raw_materials!$B:$B,raw_materials!U:U) -> 0 | Z7: =_xlfn.XLOOKUP($F7,raw_materials!$B:$B,raw_materials!V:V) -> 0 | AA7: =_xlfn.XLOOKUP($F7,raw_materials!$B:$B,raw_materials!W:W) -> 0 | AB7: =_xlfn.XLOOKUP($F7,raw_materials!$B:$B,raw_materials!X:X) -> 0 | AC7: =_xlfn.XLOOKUP($F7,raw_materials!$B:$B,raw_materials!Y:Y) -> 0 | AD7: =_xlfn.XLOOKUP($F7,raw_materials!$B:$B,raw_materials!Z:Z) -> 0 | AE7: =_xlfn.XLOOKUP($F7,raw_materials!$B:$B,raw_materials!AA:AA) -> 0 | AF7: =_xlfn.XLOOKUP($F7,raw_materials!$B:$B,raw_materials!AB:AB) -> 0 | AG7: =_xlfn.XLOOKUP($F7,raw_materials!$B:$B,raw_materials!AC:AC) -> 0 | AH7: =_xlfn.XLOOKUP($F7,raw_materials!$B:$B,raw_materials!AD:AD) -> 0 | AI7: =_xlfn.XLOOKUP($F7,raw_materials!$B:$B,raw_materials!AE:AE) -> 0 | AJ7: =_xlfn.XLOOKUP($F7,raw_materials!$B:$B,raw_materials!AF:AF) -> 0 | AK7: =_xlfn.XLOOKUP($F7,raw_materials!$B:$B,raw_materials!AG:AG) -> 0 | AL7: =_xlfn.XLOOKUP($F7,raw_materials!$B:$B,raw_materials!AH:AH) -> 0 | AM7: =_xlfn.XLOOKUP($F7,raw_materials!$B:$B,raw_materials!AI:AI) -> 0 | AN7: =_xlfn.XLOOKUP($F7,raw_materials!$B:$B,raw_materials!AJ:AJ) -> 0 | AO7: =_xlfn.XLOOKUP($F7,raw_materials!$B:$B,raw_materials!AK:AK) -> 0 | AP7: =_xlfn.XLOOKUP($F7,raw_materials!$B:$B,raw_materials!AL:AL) -> 0 | AQ7: =_xlfn.XLOOKUP($F7,raw_materials!$B:$B,raw_materials!AM:AM) -> 0 | AR7: =_xlfn.XLOOKUP($F7,raw_materials!$B:$B,raw_materials!AN:AN) -> 0 | AS7: =_xlfn.XLOOKUP($F7,raw_materials!$B:$B,raw_materials!AO:AO) -> 0 | AT7: =_xlfn.XLOOKUP($F7,raw_materials!$B:$B,raw_materials!AP:AP) -> 0 | AU7: =_xlfn.XLOOKUP($F7,raw_materials!$B:$B,raw_materials!AQ:AQ) -> 0 | AV7: =_xlfn.XLOOKUP($F7,raw_materials!$B:$B,raw_materials!AR:AR) -> 0 | AW7: =_xlfn.XLOOKUP($F7,raw_materials!$B:$B,raw_materials!AS:AS) -> 0 | AX7: =_xlfn.XLOOKUP($F7,raw_materials!$B:$B,raw_materials!AT:AT) -> 0 | AY7: =_xlfn.XLOOKUP($F7,raw_materials!$B:$B,raw_materials!AU:AU) -> 0 | AZ7: =_xlfn.XLOOKUP($F7,raw_materials!$B:$B,raw_materials!AV:AV) -> 0 | BA7: =_xlfn.XLOOKUP($F7,raw_materials!$B:$B,raw_materials!AW:AW) -> 0 | BB7: =_xlfn.XLOOKUP($F7,raw_materials!$B:$B,raw_materials!AX:AX) -> 0 | BC7: =_xlfn.XLOOKUP($F7,raw_materials!$B:$B,raw_materials!AY:AY) -> 0 | BD7: =_xlfn.XLOOKUP($F7,raw_materials!$B:$B,raw_materials!AZ:AZ) -> 0 | BE7: =_xlfn.XLOOKUP($F7,raw_materials!$B:$B,raw_materials!BA:BA) -> 0 | BF7: =_xlfn.XLOOKUP($F7,raw_materials!$B:$B,raw_materials!BB:BB) -> 0 | BG7: =_xlfn.XLOOKUP($F7,raw_materials!$B:$B,raw_materials!BC:BC) -> 0 | BH7: =_xlfn.XLOOKUP($F7,raw_materials!$B:$B,raw_materials!BD:BD) -> 0 | BI7: =_xlfn.XLOOKUP($F7,raw_materials!$B:$B,raw_materials!BE:BE) -> 0 | BJ7: =_xlfn.XLOOKUP($F7,raw_materials!$B:$B,raw_materials!BF:BF) -> 0 | BK7: =_xlfn.XLOOKUP($F7,raw_materials!$B:$B,raw_materials!BG:BG) -> 0 | BL7: =_xlfn.XLOOKUP($F7,raw_materials!$B:$B,raw_materials!BH:BH) -> 0 | BM7: =_xlfn.XLOOKUP($F7,raw_materials!$B:$B,raw_materials!BI:BI) -> 0 | BN7: =_xlfn.XLOOKUP($F7,raw_materials!$B:$B,raw_materials!BJ:BJ) -> 0 | BO7: =_xlfn.XLOOKUP($F7,raw_materials!$B:$B,raw_materials!BK:BK) -> 0
A8: 7 | B8: Bruschetta Alla Nduja | C8: Bruschetta Alla Nduja | D8: 12 | E8: 4200 | F8: Bruschetta Alla Nduja | G8: =_xlfn.XLOOKUP(F8,[1]Table0!$A:$A,[1]Table0!$B:$B) -> Pizza 1 | H8: =_xlfn.XLOOKUP($F8,raw_materials!$B:$B,raw_materials!D:D) -> Impasto Bruschetta | I8: =_xlfn.XLOOKUP($F8,raw_materials!$B:$B,raw_materials!E:E) -> 100 | J8: =_xlfn.XLOOKUP($F8,raw_materials!$B:$B,raw_materials!F:F) -> GM | K8: =_xlfn.XLOOKUP($F8,raw_materials!$B:$B,raw_materials!G:G) -> All | L8: =_xlfn.XLOOKUP($F8,raw_materials!$B:$B,raw_materials!H:H) -> Roasted Cherry Tomato | M8: =_xlfn.XLOOKUP($F8,raw_materials!$B:$B,raw_materials!I:I) -> 50 | N8: =_xlfn.XLOOKUP($F8,raw_materials!$B:$B,raw_materials!J:J) -> GM | O8: =_xlfn.XLOOKUP($F8,raw_materials!$B:$B,raw_materials!K:K) -> All | P8: =_xlfn.XLOOKUP($F8,raw_materials!$B:$B,raw_materials!L:L) -> Ricotta Cheese | Q8: =_xlfn.XLOOKUP($F8,raw_materials!$B:$B,raw_materials!M:M) -> 60 | R8: =_xlfn.XLOOKUP($F8,raw_materials!$B:$B,raw_materials!N:N) -> GM | S8: =_xlfn.XLOOKUP($F8,raw_materials!$B:$B,raw_materials!O:O) -> All | T8: =_xlfn.XLOOKUP($F8,raw_materials!$B:$B,raw_materials!P:P) -> Nduja | U8: =_xlfn.XLOOKUP($F8,raw_materials!$B:$B,raw_materials!Q:Q) -> 50 | V8: =_xlfn.XLOOKUP($F8,raw_materials!$B:$B,raw_materials!R:R) -> GM | W8: =_xlfn.XLOOKUP($F8,raw_materials!$B:$B,raw_materials!S:S) -> All | X8: =_xlfn.XLOOKUP($F8,raw_materials!$B:$B,raw_materials!T:T) -> Basil Leaves | Y8: =_xlfn.XLOOKUP($F8,raw_materials!$B:$B,raw_materials!U:U) -> 10 | Z8: =_xlfn.XLOOKUP($F8,raw_materials!$B:$B,raw_materials!V:V) -> GM | AA8: =_xlfn.XLOOKUP($F8,raw_materials!$B:$B,raw_materials!W:W) -> All | AB8: =_xlfn.XLOOKUP($F8,raw_materials!$B:$B,raw_materials!X:X) -> 0 | AC8: =_xlfn.XLOOKUP($F8,raw_materials!$B:$B,raw_materials!Y:Y) -> 0 | AD8: =_xlfn.XLOOKUP($F8,raw_materials!$B:$B,raw_materials!Z:Z) -> 0 | AE8: =_xlfn.XLOOKUP($F8,raw_materials!$B:$B,raw_materials!AA:AA) -> 0 | AF8: =_xlfn.XLOOKUP($F8,raw_materials!$B:$B,raw_materials!AB:AB) -> 0 | AG8: =_xlfn.XLOOKUP($F8,raw_materials!$B:$B,raw_materials!AC:AC) -> 0 | AH8: =_xlfn.XLOOKUP($F8,raw_materials!$B:$B,raw_materials!AD:AD) -> 0 | AI8: =_xlfn.XLOOKUP($F8,raw_materials!$B:$B,raw_materials!AE:AE) -> 0 | AJ8: =_xlfn.XLOOKUP($F8,raw_materials!$B:$B,raw_materials!AF:AF) -> 0 | AK8: =_xlfn.XLOOKUP($F8,raw_materials!$B:$B,raw_materials!AG:AG) -> 0 | AL8: =_xlfn.XLOOKUP($F8,raw_materials!$B:$B,raw_materials!AH:AH) -> 0 | AM8: =_xlfn.XLOOKUP($F8,raw_materials!$B:$B,raw_materials!AI:AI) -> 0 | AN8: =_xlfn.XLOOKUP($F8,raw_materials!$B:$B,raw_materials!AJ:AJ) -> 0 | AO8: =_xlfn.XLOOKUP($F8,raw_materials!$B:$B,raw_materials!AK:AK) -> 0 | AP8: =_xlfn.XLOOKUP($F8,raw_materials!$B:$B,raw_materials!AL:AL) -> 0 | AQ8: =_xlfn.XLOOKUP($F8,raw_materials!$B:$B,raw_materials!AM:AM) -> 0 | AR8: =_xlfn.XLOOKUP($F8,raw_materials!$B:$B,raw_materials!AN:AN) -> 0 | AS8: =_xlfn.XLOOKUP($F8,raw_materials!$B:$B,raw_materials!AO:AO) -> 0 | AT8: =_xlfn.XLOOKUP($F8,raw_materials!$B:$B,raw_materials!AP:AP) -> 0 | AU8: =_xlfn.XLOOKUP($F8,raw_materials!$B:$B,raw_materials!AQ:AQ) -> 0 | AV8: =_xlfn.XLOOKUP($F8,raw_materials!$B:$B,raw_materials!AR:AR) -> 0 | AW8: =_xlfn.XLOOKUP($F8,raw_materials!$B:$B,raw_materials!AS:AS) -> 0 | AX8: =_xlfn.XLOOKUP($F8,raw_materials!$B:$B,raw_materials!AT:AT) -> 0 | AY8: =_xlfn.XLOOKUP($F8,raw_materials!$B:$B,raw_materials!AU:AU) -> 0 | AZ8: =_xlfn.XLOOKUP($F8,raw_materials!$B:$B,raw_materials!AV:AV) -> 0 | BA8: =_xlfn.XLOOKUP($F8,raw_materials!$B:$B,raw_materials!AW:AW) -> 0 | BB8: =_xlfn.XLOOKUP($F8,raw_materials!$B:$B,raw_materials!AX:AX) -> 0 | BC8: =_xlfn.XLOOKUP($F8,raw_materials!$B:$B,raw_materials!AY:AY) -> 0 | BD8: =_xlfn.XLOOKUP($F8,raw_materials!$B:$B,raw_materials!AZ:AZ) -> 0 | BE8: =_xlfn.XLOOKUP($F8,raw_materials!$B:$B,raw_materials!BA:BA) -> 0 | BF8: =_xlfn.XLOOKUP($F8,raw_materials!$B:$B,raw_materials!BB:BB) -> 0 | BG8: =_xlfn.XLOOKUP($F8,raw_materials!$B:$B,raw_materials!BC:BC) -> 0 | BH8: =_xlfn.XLOOKUP($F8,raw_materials!$B:$B,raw_materials!BD:BD) -> 0 | BI8: =_xlfn.XLOOKUP($F8,raw_materials!$B:$B,raw_materials!BE:BE) -> 0 | BJ8: =_xlfn.XLOOKUP($F8,raw_materials!$B:$B,raw_materials!BF:BF) -> 0 | BK8: =_xlfn.XLOOKUP($F8,raw_materials!$B:$B,raw_materials!BG:BG) -> 0 | BL8: =_xlfn.XLOOKUP($F8,raw_materials!$B:$B,raw_materials!BH:BH) -> 0 | BM8: =_xlfn.XLOOKUP($F8,raw_materials!$B:$B,raw_materials!BI:BI) -> 0 | BN8: =_xlfn.XLOOKUP($F8,raw_materials!$B:$B,raw_materials!BJ:BJ) -> 0 | BO8: =_xlfn.XLOOKUP($F8,raw_materials!$B:$B,raw_materials!BK:BK) -> 0
A9: 8 | B9: Bruschetta Con Pate' Di Olive | C9: Bruschetta Con Pate' Di Olive | D9: 20 | E9: 5900 | F9: Bruschetta Con Pate' Di Olive | G9: =_xlfn.XLOOKUP(F9,[1]Table0!$A:$A,[1]Table0!$B:$B) -> Pizza 1 | H9: =_xlfn.XLOOKUP($F9,raw_materials!$B:$B,raw_materials!D:D) -> Impasto Bruschetta | I9: =_xlfn.XLOOKUP($F9,raw_materials!$B:$B,raw_materials!E:E) -> 100 | J9: =_xlfn.XLOOKUP($F9,raw_materials!$B:$B,raw_materials!F:F) -> GM | K9: =_xlfn.XLOOKUP($F9,raw_materials!$B:$B,raw_materials!G:G) -> All | L9: =_xlfn.XLOOKUP($F9,raw_materials!$B:$B,raw_materials!H:H) -> Cauliflower Cream | M9: =_xlfn.XLOOKUP($F9,raw_materials!$B:$B,raw_materials!I:I) -> 80 | N9: =_xlfn.XLOOKUP($F9,raw_materials!$B:$B,raw_materials!J:J) -> GM | O9: =_xlfn.XLOOKUP($F9,raw_materials!$B:$B,raw_materials!K:K) -> All | P9: =_xlfn.XLOOKUP($F9,raw_materials!$B:$B,raw_materials!L:L) -> Olive Paste | Q9: =_xlfn.XLOOKUP($F9,raw_materials!$B:$B,raw_materials!M:M) -> 40 | R9: =_xlfn.XLOOKUP($F9,raw_materials!$B:$B,raw_materials!N:N) -> GM | S9: =_xlfn.XLOOKUP($F9,raw_materials!$B:$B,raw_materials!O:O) -> All | T9: =_xlfn.XLOOKUP($F9,raw_materials!$B:$B,raw_materials!P:P) -> 0 | U9: =_xlfn.XLOOKUP($F9,raw_materials!$B:$B,raw_materials!Q:Q) -> 0 | V9: =_xlfn.XLOOKUP($F9,raw_materials!$B:$B,raw_materials!R:R) -> 0 | W9: =_xlfn.XLOOKUP($F9,raw_materials!$B:$B,raw_materials!S:S) -> 0 | X9: =_xlfn.XLOOKUP($F9,raw_materials!$B:$B,raw_materials!T:T) -> 0 | Y9: =_xlfn.XLOOKUP($F9,raw_materials!$B:$B,raw_materials!U:U) -> 0 | Z9: =_xlfn.XLOOKUP($F9,raw_materials!$B:$B,raw_materials!V:V) -> 0 | AA9: =_xlfn.XLOOKUP($F9,raw_materials!$B:$B,raw_materials!W:W) -> 0 | AB9: =_xlfn.XLOOKUP($F9,raw_materials!$B:$B,raw_materials!X:X) -> 0 | AC9: =_xlfn.XLOOKUP($F9,raw_materials!$B:$B,raw_materials!Y:Y) -> 0 | AD9: =_xlfn.XLOOKUP($F9,raw_materials!$B:$B,raw_materials!Z:Z) -> 0 | AE9: =_xlfn.XLOOKUP($F9,raw_materials!$B:$B,raw_materials!AA:AA) -> 0 | AF9: =_xlfn.XLOOKUP($F9,raw_materials!$B:$B,raw_materials!AB:AB) -> 0 | AG9: =_xlfn.XLOOKUP($F9,raw_materials!$B:$B,raw_materials!AC:AC) -> 0 | AH9: =_xlfn.XLOOKUP($F9,raw_materials!$B:$B,raw_materials!AD:AD) -> 0 | AI9: =_xlfn.XLOOKUP($F9,raw_materials!$B:$B,raw_materials!AE:AE) -> 0 | AJ9: =_xlfn.XLOOKUP($F9,raw_materials!$B:$B,raw_materials!AF:AF) -> 0 | AK9: =_xlfn.XLOOKUP($F9,raw_materials!$B:$B,raw_materials!AG:AG) -> 0 | AL9: =_xlfn.XLOOKUP($F9,raw_materials!$B:$B,raw_materials!AH:AH) -> 0 | AM9: =_xlfn.XLOOKUP($F9,raw_materials!$B:$B,raw_materials!AI:AI) -> 0 | AN9: =_xlfn.XLOOKUP($F9,raw_materials!$B:$B,raw_materials!AJ:AJ) -> 0 | AO9: =_xlfn.XLOOKUP($F9,raw_materials!$B:$B,raw_materials!AK:AK) -> 0 | AP9: =_xlfn.XLOOKUP($F9,raw_materials!$B:$B,raw_materials!AL:AL) -> 0 | AQ9: =_xlfn.XLOOKUP($F9,raw_materials!$B:$B,raw_materials!AM:AM) -> 0 | AR9: =_xlfn.XLOOKUP($F9,raw_materials!$B:$B,raw_materials!AN:AN) -> 0 | AS9: =_xlfn.XLOOKUP($F9,raw_materials!$B:$B,raw_materials!AO:AO) -> 0 | AT9: =_xlfn.XLOOKUP($F9,raw_materials!$B:$B,raw_materials!AP:AP) -> 0 | AU9: =_xlfn.XLOOKUP($F9,raw_materials!$B:$B,raw_materials!AQ:AQ) -> 0 | AV9: =_xlfn.XLOOKUP($F9,raw_materials!$B:$B,raw_materials!AR:AR) -> 0 | AW9: =_xlfn.XLOOKUP($F9,raw_materials!$B:$B,raw_materials!AS:AS) -> 0 | AX9: =_xlfn.XLOOKUP($F9,raw_materials!$B:$B,raw_materials!AT:AT) -> 0 | AY9: =_xlfn.XLOOKUP($F9,raw_materials!$B:$B,raw_materials!AU:AU) -> 0 | AZ9: =_xlfn.XLOOKUP($F9,raw_materials!$B:$B,raw_materials!AV:AV) -> 0 | BA9: =_xlfn.XLOOKUP($F9,raw_materials!$B:$B,raw_materials!AW:AW) -> 0 | BB9: =_xlfn.XLOOKUP($F9,raw_materials!$B:$B,raw_materials!AX:AX) -> 0 | BC9: =_xlfn.XLOOKUP($F9,raw_materials!$B:$B,raw_materials!AY:AY) -> 0 | BD9: =_xlfn.XLOOKUP($F9,raw_materials!$B:$B,raw_materials!AZ:AZ) -> 0 | BE9: =_xlfn.XLOOKUP($F9,raw_materials!$B:$B,raw_materials!BA:BA) -> 0 | BF9: =_xlfn.XLOOKUP($F9,raw_materials!$B:$B,raw_materials!BB:BB) -> 0 | BG9: =_xlfn.XLOOKUP($F9,raw_materials!$B:$B,raw_materials!BC:BC) -> 0 | BH9: =_xlfn.XLOOKUP($F9,raw_materials!$B:$B,raw_materials!BD:BD) -> 0 | BI9: =_xlfn.XLOOKUP($F9,raw_materials!$B:$B,raw_materials!BE:BE) -> 0 | BJ9: =_xlfn.XLOOKUP($F9,raw_materials!$B:$B,raw_materials!BF:BF) -> 0 | BK9: =_xlfn.XLOOKUP($F9,raw_materials!$B:$B,raw_materials!BG:BG) -> 0 | BL9: =_xlfn.XLOOKUP($F9,raw_materials!$B:$B,raw_materials!BH:BH) -> 0 | BM9: =_xlfn.XLOOKUP($F9,raw_materials!$B:$B,raw_materials!BI:BI) -> 0 | BN9: =_xlfn.XLOOKUP($F9,raw_materials!$B:$B,raw_materials!BJ:BJ) -> 0 | BO9: =_xlfn.XLOOKUP($F9,raw_materials!$B:$B,raw_materials!BK:BK) -> 0
A10: 9 | B10: Vellutata Di Zucca Con Funghi | C10: Vellutata Di Zucca Con Funghi | D10: 30 | E10: 9100 | F10: Vellutata Di Zucca Con Funghi | G10: =_xlfn.XLOOKUP(F10,[1]Table0!$A:$A,[1]Table0!$B:$B) -> Italian 1 | H10: =_xlfn.XLOOKUP($F10,raw_materials!$B:$B,raw_materials!D:D) -> Crema Di Zucca | I10: =_xlfn.XLOOKUP($F10,raw_materials!$B:$B,raw_materials!E:E) -> 200 | J10: =_xlfn.XLOOKUP($F10,raw_materials!$B:$B,raw_materials!F:F) -> GM | K10: =_xlfn.XLOOKUP($F10,raw_materials!$B:$B,raw_materials!G:G) -> All | L10: =_xlfn.XLOOKUP($F10,raw_materials!$B:$B,raw_materials!H:H) -> Funghi Button Trifolati | M10: =_xlfn.XLOOKUP($F10,raw_materials!$B:$B,raw_materials!I:I) -> 15 | N10: =_xlfn.XLOOKUP($F10,raw_materials!$B:$B,raw_materials!J:J) -> GM | O10: =_xlfn.XLOOKUP($F10,raw_materials!$B:$B,raw_materials!K:K) -> All | P10: =_xlfn.XLOOKUP($F10,raw_materials!$B:$B,raw_materials!L:L) -> Crema Di Blue Cheese | Q10: =_xlfn.XLOOKUP($F10,raw_materials!$B:$B,raw_materials!M:M) -> 15 | R10: =_xlfn.XLOOKUP($F10,raw_materials!$B:$B,raw_materials!N:N) -> GM | S10: =_xlfn.XLOOKUP($F10,raw_materials!$B:$B,raw_materials!O:O) -> All | T10: =_xlfn.XLOOKUP($F10,raw_materials!$B:$B,raw_materials!P:P) -> Impasto Bruschetta | U10: =_xlfn.XLOOKUP($F10,raw_materials!$B:$B,raw_materials!Q:Q) -> 40 | V10: =_xlfn.XLOOKUP($F10,raw_materials!$B:$B,raw_materials!R:R) -> GM | W10: =_xlfn.XLOOKUP($F10,raw_materials!$B:$B,raw_materials!S:S) -> All | X10: =_xlfn.XLOOKUP($F10,raw_materials!$B:$B,raw_materials!T:T) -> 0 | Y10: =_xlfn.XLOOKUP($F10,raw_materials!$B:$B,raw_materials!U:U) -> 0 | Z10: =_xlfn.XLOOKUP($F10,raw_materials!$B:$B,raw_materials!V:V) -> 0 | AA10: =_xlfn.XLOOKUP($F10,raw_materials!$B:$B,raw_materials!W:W) -> 0 | AB10: =_xlfn.XLOOKUP($F10,raw_materials!$B:$B,raw_materials!X:X) -> 0 | AC10: =_xlfn.XLOOKUP($F10,raw_materials!$B:$B,raw_materials!Y:Y) -> 0 | AD10: =_xlfn.XLOOKUP($F10,raw_materials!$B:$B,raw_materials!Z:Z) -> 0 | AE10: =_xlfn.XLOOKUP($F10,raw_materials!$B:$B,raw_materials!AA:AA) -> 0 | AF10: =_xlfn.XLOOKUP($F10,raw_materials!$B:$B,raw_materials!AB:AB) -> 0 | AG10: =_xlfn.XLOOKUP($F10,raw_materials!$B:$B,raw_materials!AC:AC) -> 0 | AH10: =_xlfn.XLOOKUP($F10,raw_materials!$B:$B,raw_materials!AD:AD) -> 0 | AI10: =_xlfn.XLOOKUP($F10,raw_materials!$B:$B,raw_materials!AE:AE) -> 0 | AJ10: =_xlfn.XLOOKUP($F10,raw_materials!$B:$B,raw_materials!AF:AF) -> 0 | AK10: =_xlfn.XLOOKUP($F10,raw_materials!$B:$B,raw_materials!AG:AG) -> 0 | AL10: =_xlfn.XLOOKUP($F10,raw_materials!$B:$B,raw_materials!AH:AH) -> 0 | AM10: =_xlfn.XLOOKUP($F10,raw_materials!$B:$B,raw_materials!AI:AI) -> 0 | AN10: =_xlfn.XLOOKUP($F10,raw_materials!$B:$B,raw_materials!AJ:AJ) -> 0 | AO10: =_xlfn.XLOOKUP($F10,raw_materials!$B:$B,raw_materials!AK:AK) -> 0 | AP10: =_xlfn.XLOOKUP($F10,raw_materials!$B:$B,raw_materials!AL:AL) -> 0 | AQ10: =_xlfn.XLOOKUP($F10,raw_materials!$B:$B,raw_materials!AM:AM) -> 0 | AR10: =_xlfn.XLOOKUP($F10,raw_materials!$B:$B,raw_materials!AN:AN) -> 0 | AS10: =_xlfn.XLOOKUP($F10,raw_materials!$B:$B,raw_materials!AO:AO) -> 0 | AT10: =_xlfn.XLOOKUP($F10,raw_materials!$B:$B,raw_materials!AP:AP) -> 0 | AU10: =_xlfn.XLOOKUP($F10,raw_materials!$B:$B,raw_materials!AQ:AQ) -> 0 | AV10: =_xlfn.XLOOKUP($F10,raw_materials!$B:$B,raw_materials!AR:AR) -> 0 | AW10: =_xlfn.XLOOKUP($F10,raw_materials!$B:$B,raw_materials!AS:AS) -> 0 | AX10: =_xlfn.XLOOKUP($F10,raw_materials!$B:$B,raw_materials!AT:AT) -> 0 | AY10: =_xlfn.XLOOKUP($F10,raw_materials!$B:$B,raw_materials!AU:AU) -> 0 | AZ10: =_xlfn.XLOOKUP($F10,raw_materials!$B:$B,raw_materials!AV:AV) -> 0 | BA10: =_xlfn.XLOOKUP($F10,raw_materials!$B:$B,raw_materials!AW:AW) -> 0 | BB10: =_xlfn.XLOOKUP($F10,raw_materials!$B:$B,raw_materials!AX:AX) -> 0 | BC10: =_xlfn.XLOOKUP($F10,raw_materials!$B:$B,raw_materials!AY:AY) -> 0 | BD10: =_xlfn.XLOOKUP($F10,raw_materials!$B:$B,raw_materials!AZ:AZ) -> 0 | BE10: =_xlfn.XLOOKUP($F10,raw_materials!$B:$B,raw_materials!BA:BA) -> 0 | BF10: =_xlfn.XLOOKUP($F10,raw_materials!$B:$B,raw_materials!BB:BB) -> 0 | BG10: =_xlfn.XLOOKUP($F10,raw_materials!$B:$B,raw_materials!BC:BC) -> 0 | BH10: =_xlfn.XLOOKUP($F10,raw_materials!$B:$B,raw_materials!BD:BD) -> 0 | BI10: =_xlfn.XLOOKUP($F10,raw_materials!$B:$B,raw_materials!BE:BE) -> 0 | BJ10: =_xlfn.XLOOKUP($F10,raw_materials!$B:$B,raw_materials!BF:BF) -> 0 | BK10: =_xlfn.XLOOKUP($F10,raw_materials!$B:$B,raw_materials!BG:BG) -> 0 | BL10: =_xlfn.XLOOKUP($F10,raw_materials!$B:$B,raw_materials!BH:BH) -> 0 | BM10: =_xlfn.XLOOKUP($F10,raw_materials!$B:$B,raw_materials!BI:BI) -> 0 | BN10: =_xlfn.XLOOKUP($F10,raw_materials!$B:$B,raw_materials!BJ:BJ) -> 0 | BO10: =_xlfn.XLOOKUP($F10,raw_materials!$B:$B,raw_materials!BK:BK) -> 0
A11: 10 | B11: Minestrone Con Polpette | C11: Minestrone Con Polpette | D11: 15 | E11: 5475 | F11: Minestrone Con Polpette | G11: =_xlfn.XLOOKUP(F11,[1]Table0!$A:$A,[1]Table0!$B:$B) -> Italian 1 | H11: =_xlfn.XLOOKUP($F11,raw_materials!$B:$B,raw_materials!D:D) -> Minestrone | I11: =_xlfn.XLOOKUP($F11,raw_materials!$B:$B,raw_materials!E:E) -> 250 | J11: =_xlfn.XLOOKUP($F11,raw_materials!$B:$B,raw_materials!F:F) -> GM | K11: =_xlfn.XLOOKUP($F11,raw_materials!$B:$B,raw_materials!G:G) -> All | L11: =_xlfn.XLOOKUP($F11,raw_materials!$B:$B,raw_materials!H:H) -> Polpetta Di Pollo | M11: =_xlfn.XLOOKUP($F11,raw_materials!$B:$B,raw_materials!I:I) -> 75 | N11: =_xlfn.XLOOKUP($F11,raw_materials!$B:$B,raw_materials!J:J) -> GM | O11: =_xlfn.XLOOKUP($F11,raw_materials!$B:$B,raw_materials!K:K) -> All | P11: =_xlfn.XLOOKUP($F11,raw_materials!$B:$B,raw_materials!L:L) -> Grana Padano | Q11: =_xlfn.XLOOKUP($F11,raw_materials!$B:$B,raw_materials!M:M) -> 20 | R11: =_xlfn.XLOOKUP($F11,raw_materials!$B:$B,raw_materials!N:N) -> GM | S11: =_xlfn.XLOOKUP($F11,raw_materials!$B:$B,raw_materials!O:O) -> All | T11: =_xlfn.XLOOKUP($F11,raw_materials!$B:$B,raw_materials!P:P) -> Impasto Bruschetta | U11: =_xlfn.XLOOKUP($F11,raw_materials!$B:$B,raw_materials!Q:Q) -> 50 | V11: =_xlfn.XLOOKUP($F11,raw_materials!$B:$B,raw_materials!R:R) -> GM | W11: =_xlfn.XLOOKUP($F11,raw_materials!$B:$B,raw_materials!S:S) -> All | X11: =_xlfn.XLOOKUP($F11,raw_materials!$B:$B,raw_materials!T:T) -> 0 | Y11: =_xlfn.XLOOKUP($F11,raw_materials!$B:$B,raw_materials!U:U) -> 0 | Z11: =_xlfn.XLOOKUP($F11,raw_materials!$B:$B,raw_materials!V:V) -> 0 | AA11: =_xlfn.XLOOKUP($F11,raw_materials!$B:$B,raw_materials!W:W) -> 0 | AB11: =_xlfn.XLOOKUP($F11,raw_materials!$B:$B,raw_materials!X:X) -> 0 | AC11: =_xlfn.XLOOKUP($F11,raw_materials!$B:$B,raw_materials!Y:Y) -> 0 | AD11: =_xlfn.XLOOKUP($F11,raw_materials!$B:$B,raw_materials!Z:Z) -> 0 | AE11: =_xlfn.XLOOKUP($F11,raw_materials!$B:$B,raw_materials!AA:AA) -> 0 | AF11: =_xlfn.XLOOKUP($F11,raw_materials!$B:$B,raw_materials!AB:AB) -> 0 | AG11: =_xlfn.XLOOKUP($F11,raw_materials!$B:$B,raw_materials!AC:AC) -> 0 | AH11: =_xlfn.XLOOKUP($F11,raw_materials!$B:$B,raw_materials!AD:AD) -> 0 | AI11: =_xlfn.XLOOKUP($F11,raw_materials!$B:$B,raw_materials!AE:AE) -> 0 | AJ11: =_xlfn.XLOOKUP($F11,raw_materials!$B:$B,raw_materials!AF:AF) -> 0 | AK11: =_xlfn.XLOOKUP($F11,raw_materials!$B:$B,raw_materials!AG:AG) -> 0 | AL11: =_xlfn.XLOOKUP($F11,raw_materials!$B:$B,raw_materials!AH:AH) -> 0 | AM11: =_xlfn.XLOOKUP($F11,raw_materials!$B:$B,raw_materials!AI:AI) -> 0 | AN11: =_xlfn.XLOOKUP($F11,raw_materials!$B:$B,raw_materials!AJ:AJ) -> 0 | AO11: =_xlfn.XLOOKUP($F11,raw_materials!$B:$B,raw_materials!AK:AK) -> 0 | AP11: =_xlfn.XLOOKUP($F11,raw_materials!$B:$B,raw_materials!AL:AL) -> 0 | AQ11: =_xlfn.XLOOKUP($F11,raw_materials!$B:$B,raw_materials!AM:AM) -> 0 | AR11: =_xlfn.XLOOKUP($F11,raw_materials!$B:$B,raw_materials!AN:AN) -> 0 | AS11: =_xlfn.XLOOKUP($F11,raw_materials!$B:$B,raw_materials!AO:AO) -> 0 | AT11: =_xlfn.XLOOKUP($F11,raw_materials!$B:$B,raw_materials!AP:AP) -> 0 | AU11: =_xlfn.XLOOKUP($F11,raw_materials!$B:$B,raw_materials!AQ:AQ) -> 0 | AV11: =_xlfn.XLOOKUP($F11,raw_materials!$B:$B,raw_materials!AR:AR) -> 0 | AW11: =_xlfn.XLOOKUP($F11,raw_materials!$B:$B,raw_materials!AS:AS) -> 0 | AX11: =_xlfn.XLOOKUP($F11,raw_materials!$B:$B,raw_materials!AT:AT) -> 0 | AY11: =_xlfn.XLOOKUP($F11,raw_materials!$B:$B,raw_materials!AU:AU) -> 0 | AZ11: =_xlfn.XLOOKUP($F11,raw_materials!$B:$B,raw_materials!AV:AV) -> 0 | BA11: =_xlfn.XLOOKUP($F11,raw_materials!$B:$B,raw_materials!AW:AW) -> 0 | BB11: =_xlfn.XLOOKUP($F11,raw_materials!$B:$B,raw_materials!AX:AX) -> 0 | BC11: =_xlfn.XLOOKUP($F11,raw_materials!$B:$B,raw_materials!AY:AY) -> 0 | BD11: =_xlfn.XLOOKUP($F11,raw_materials!$B:$B,raw_materials!AZ:AZ) -> 0 | BE11: =_xlfn.XLOOKUP($F11,raw_materials!$B:$B,raw_materials!BA:BA) -> 0 | BF11: =_xlfn.XLOOKUP($F11,raw_materials!$B:$B,raw_materials!BB:BB) -> 0 | BG11: =_xlfn.XLOOKUP($F11,raw_materials!$B:$B,raw_materials!BC:BC) -> 0 | BH11: =_xlfn.XLOOKUP($F11,raw_materials!$B:$B,raw_materials!BD:BD) -> 0 | BI11: =_xlfn.XLOOKUP($F11,raw_materials!$B:$B,raw_materials!BE:BE) -> 0 | BJ11: =_xlfn.XLOOKUP($F11,raw_materials!$B:$B,raw_materials!BF:BF) -> 0 | BK11: =_xlfn.XLOOKUP($F11,raw_materials!$B:$B,raw_materials!BG:BG) -> 0 | BL11: =_xlfn.XLOOKUP($F11,raw_materials!$B:$B,raw_materials!BH:BH) -> 0 | BM11: =_xlfn.XLOOKUP($F11,raw_materials!$B:$B,raw_materials!BI:BI) -> 0 | BN11: =_xlfn.XLOOKUP($F11,raw_materials!$B:$B,raw_materials!BJ:BJ) -> 0 | BO11: =_xlfn.XLOOKUP($F11,raw_materials!$B:$B,raw_materials!BK:BK) -> 0
